<mujoco model="ur5">
    <compiler angle="radian" meshdir="meshes" />

    <option cone="elliptic" timestep="0.02" />

    <size njmax="500" nconmax="100" />

    <visual>
        <map znear="0.001" />
    </visual>

    <default>
        <light castshadow="false" diffuse="1 1 1" />
        <joint frictionloss="1" damping="1" />
        <camera fovy="60" />
        <motor gear="0.8"/>
        <velocity kv="10"/>
        <position kp="5"/>
    </default>

    <asset>
        <mesh file="base.stl" />
        <mesh file="shoulder.stl" />
        <mesh file="upperarm.stl" />
        <mesh file="forearm.stl" />
        <mesh file="wrist1.stl" />
        <mesh file="wrist2.stl" />
        <mesh file="wrist3.stl" />
        <mesh file="kinova_robotiq_coupler.stl" />
        <mesh file="robotiq_85_base_link.stl" />
        <mesh file="robotiq_85_finger_link.stl" />
        <mesh file="robotiq_85_finger_tip_link.stl" />
        <mesh file="robotiq_85_inner_knuckle_link.stl" />
        <mesh file="robotiq_85_knuckle_link.stl" />
        <material name="RobMat" specular="0.9" shininess="0.5" reflectance="0" rgba="0.7 0.7 0.7 1" emission="0.1" />
        <material name="GriMat" specular="0.9" shininess="0.5" reflectance="0" rgba="0.1 0.1 0.1 1" emission="0.1" />
        <material name="BasketMat" specular="0" shininess="0" reflectance="0" rgba="0.26 0.16 0.16796875 1" emission="0" />
        <material name="Light" specular="0" shininess="0.6" reflectance="0.9" rgba="0.5 0.5 1 1" emission="0.7" />
    </asset>

    <worldbody>
        <body pos="-0.16 0.90 0.02" euler="4.71238898 0 3.14159265">
            <body euler="0 -0.82 0">
                <camera name="workbench_camera" euler="0.25 0 0" fovy="43" />
            </body>
        </body>
        <body pos="-1 1.52 0.64" euler="4.71238898 0 3.14159265">
            <body euler="-0.23 0 0">
                <camera name="upper_camera" euler="0 0.09 0" fovy="41" />
            </body>
        </body>

        <light directional="true" pos="-0.5 0.5 3" dir="0 0 -1" />
        <light directional="false" pos="-0.5 0.5 1.5" dir="0 -1 0" />
        <geom name="workbench_down" pos="-0.6 0.6 -0.25" size="0.6 0.6 0.25" type="box" rgba="0.1 0.1 0.1 1" material="BasketMat" />
        <geom name="floor" pos="0 0 -0.66" size="10 10 1" type="plane" rgba="1 0.83 0.61 1" material="BasketMat" />


        <body name="target_body_1" pos="0 0 0.05">
            <geom name="target_1" pos="0 0 0" size="0.05 0.05 0.05" type="box" rgba="0.9529411765 0.8 0.03529411765 1" />
            <joint name="free_x_1" pos="0 0 0" type="slide" ref="0.6" axis="1 0 0" />
            <joint name="free_y_1" pos="0 0 0" type="slide" ref="-0.6" axis="0 1 0" />
        </body>

        <body name="target_body_2" pos="0 0 0.05">
            <geom name="target_2" pos="0 0 0" size="0.05 0.05 0.05" type="box" rgba="0.01568627451 0.262745098 0.6392156863 1" />
            <joint name="free_x_2" pos="0 0 0" type="slide" ref="0.6" axis="1 0 0" />
            <joint name="free_y_2" pos="0 0 0" type="slide" ref="-0.6" axis="0 1 0" />
        </body>

        <body name="target_body_3" pos="0 0 0.05">
            <geom name="target_3" pos="0 0 0" size="0.05 0.05 0.05" type="box" rgba="0.08235294118 0.3058823529 0.03529411765 1" />
            <joint name="free_x_3" pos="0 0 0" type="slide" ref="0.6" axis="1 0 0" />
            <joint name="free_y_3" pos="0 0 0" type="slide" ref="-0.6" axis="0 1 0" />
        </body>

        <body name="target_body_4" pos="0 0 0.05">
            <geom name="target_4" pos="0 0 0" size="0.05 0.05 0.05" type="box" rgba="0.4941176471 0.1176470588 0.04705882353 1" />
            <joint name="free_x_4" pos="0 0 0" type="slide" ref="0.6" axis="1 0 0" />
            <joint name="free_y_4" pos="0 0 0" type="slide" ref="-0.6" axis="0 1 0" />
        </body>

    </worldbody>

</mujoco>
